Workbook

Sheet stats
A1: TPU Since Inception | D1: Last Update: | E1: 45383
A2: Number of Trades | B2: =COUNT('closed since inception'!G:G) -> 149
A3: Number of Winners | B3: =COUNTIF('closed since inception'!G:G,">0") -> 79
A4: Win rate | B4: =COUNTIF('closed since inception'!G:G,">0")/COUNT('closed since inception'!G:G) -> 0.53020134
A5: Avg Return | B5: =AVERAGE('closed since inception'!G:G) -> -0.00068473187
A6: Avg weighted return | B6: =SUM('closed since inception'!H:H) -> -0.011477016
A7: Avg duration | B7: =AVERAGE('closed since inception'!I:I) -> 139.6443
A10: YTD
A11: Number of Trades | B11: =COUNT(YTD!G:G) -> 17
A12: Number of Winners | B12: =COUNTIF(YTD!G:G,">0") -> 12
A13: Win rate | B13: =COUNTIF(YTD!G2:G48,">0")/COUNT(YTD!G2:G48) -> 0.70588235
A14: Avg Return | B14: =AVERAGE(YTD!G:G) -> 0.10192353
A15: Avg weighted return | B15: =SUM(YTD!H:H) -> 0.10013161
A16: Avg duration | B16: =AVERAGE(YTD!I:I) -> 258.17647
A19: Top 10 (inception)
A20: rank | B20: Ticker Symbol | C20: Weight | D20: Entry Date | E20: Entry Price | F20: Exit Date | G20: Gain % | H20: Days Held
A21: 1 | B21: RYCEY | C21: 1 | D21: 44651 | E21: 1.14 | F21: 45267 | G21: 2.167 | H21: =_xlfn.DAYS(F21,D21) -> 616
A22: 2 | B22: BIIB | C22: 1 | D22: 44245 | E22: -55.02 | F22: 44354 | G22: 0.728 | H22: 109
A23: 3 | B23: F | C23: 1 | D23: 44427 | E23: 12.75 | F23: 44574 | G23: 0.50372549 | H23: 147
A24: 4 | B24: JSPR | C24: 1 | D24: 44476 | E24: 8.5 | F24: 44482 | G24: 0.50029412 | H24: 6
A25: 5 | B25: TRIP | C25: 1 | D25: 44175 | E25: 29.05 | F25: 44250 | G25: 0.48803787 | H25: 75
A26: 6 | B26: RKT | C26: 1 | D26: 44231 | E26: 21.56 | F26: 44258 | G26: 0.43286178 | H26: 27
A27: 7 | B27: SOUN | C27: 1 | D27: 45357 | E27: 5.17 | F27: 45365 | G27: 0.425 | H27: 8
A28: 8 | B28: SOFI | C28: 1 | D28: 44932 | E28: 4.53 | F28: 44966 | G28: 0.38741722 | H28: 34
A29: 9 | B29: CYRX | C29: 1 | D29: 44153 | E29: 48.85 | F29: 44222 | G29: 0.35757421 | H29: 69
A30: 10 | B30: BA | C30: 1 | D30: 44819 | E30: 147.88 | F30: 45187 | G30: 0.3494 | H30: =F30-D30 -> 368
A32: Top 5 (ytd)
A33: rank | B33: Ticker Symbol | C33: Weight | D33: Entry Date | E33: Entry Price | F33: Exit Date | G33: Gain % | H33: Days Held
A34: 1 | B34: SOUN | C34: 1 | D34: 45357 | E34: 5.17 | F34: 45365 | G34: 0.425 | H34: 8
A35: 2 | B35: ET | C35: 1 | D35: 44827 | E35: 11 | F35: 45309 | G35: 0.3417 | H35: =_xlfn.DAYS(F35,D35) -> 482
A36: 3 | B36: TTD | C36: 1 | D36: 45302 | E36: 68.6 | F36: 45366 | G36: 0.2483 | H36: =_xlfn.DAYS(F36,D36) -> 64
A37: 4 | B37: VRTX | C37: 1 | D37: 45239 | E37: 42.27 | F37: 45309 | G37: 0.2184 | H37: =_xlfn.DAYS(F37,D37) -> 70
A38: 5 | B38: ET | C38: 1 | D38: 45026 | E38: 12.5 | F38: 45309 | G38: 0.1784 | H38: =_xlfn.DAYS(F38,D38) -> 283

Sheet closed since inception
A1: Ticker Symbol | B1: Weight | C1: Entry Date | D1: Entry Price | E1: Exit Date | F1: Exit Price | G1: Gain % | I1: Days Held | K1: Open Editor | L1: Dividends | M1: Close Editor
A2: USAS | B2: 0.5 | C2: 44133 | D2: 2.43 | E2: 44144 | F2: 2.78 | G2: 0.144 | H2: =G2*B2/SUM(B:B) -> 0.00045827764 | I2: 11 | K2: Karim | L2: 0
A3: CYRX | B3: 1 | C3: 44153 | D3: 48.85 | E3: 44222 | G3: 0.35757421 | H3: =G3*B3/SUM(B:B) -> 0.0022759481 | I3: 69
A4: LYV | B4: 1 | C4: 44217 | D4: -14.3 | E4: 44231 | F4: 15.1 | G4: 0.056 | H4: =G4*B4/SUM(B:B) -> 0.00035643816 | I4: 14
A5: LH | B5: 0.2 | C5: 44126 | D5: 204.54 | E5: 44245 | F5: 241.69 | G5: 0.182 | H5: =G5*B5/SUM(B:B) -> 0.00023168481 | I5: 119 | K5: Bryan | L5: 0
A6: DGX | B6: 0.2 | C6: 44126 | D6: 121.44 | E6: 44245 | F6: 121.18 | G6: 0.002 | H6: =G6*B6/SUM(B:B) -> 2.5459869e-06 | I6: 119 | K6: Bryan | L6: 0.11
A7: TTCF | B7: 1 | C7: 44140 | D7: 18.63 | E7: 44249 | G7: 0.23590982 | H7: =G7*B7/SUM(B:B) -> 0.0015015583 | I7: 109
A8: TRIP | B8: 1 | C8: 44175 | D8: 29.05 | E8: 44250 | G8: 0.48803787 | H8: =G8*B8/SUM(B:B) -> 0.003106345 | I8: 75
A9: RKT | B9: 1 | C9: 44231 | D9: 21.56 | E9: 44258 | G9: 0.43286178 | H9: =G9*B9/SUM(B:B) -> 0.002755151 | I9: 27
A10: VGAC | B10: 1 | C10: 44238 | D10: 14.34 | E10: 44260 | F10: 10.74 | G10: -0.251 | H10: =G10*B10/SUM(B:B) -> -0.0015976068 | I10: 22 | K10: Karim | L10: 0
A11: GMBL | B11: 1 | C11: 44259 | D11: 19.26 | E11: 44264 | F11: 14.44 | G11: -0.25 | H11: =G11*B11/SUM(B:B) -> -0.0015912418 | I11: 5 | K11: Bryan | L11: 0
A12: ABNB | B12: 1 | C12: 44260 | D12: 166.5 | E12: 44280 | F12: 191.65 | G12: 0.151 | H12: =G12*B12/SUM(B:B) -> 0.00096111005 | I12: 20
A13: CLF | B13: 1 | C13: 44280 | D13: 14.27 | E13: 44294 | F13: 17.9 | G13: 0.254 | H13: =G13*B13/SUM(B:B) -> 0.0016167017 | I13: 14
A14: HOFV | B14: 1 | C14: 44287 | D14: 5.3 | E14: 44298 | F14: 3.96 | G14: -0.253 | H14: =G14*B14/SUM(B:B) -> -0.0016103367 | I14: 11 | K14: Bryan Bottarelli | L14: 0
A15: REYN | B15: 1 | C15: 44196 | D15: 30.13 | E15: 44308 | F15: 30.77 | G15: 0.029 | H15: =G15*B15/SUM(B:B) -> 0.00018458405 | I15: 112 | K15: Karim | L15: 0.23
A16: F | B16: 1 | C16: 44210 | D16: 9.81 | E16: 44315 | G16: -1 | H16: =G16*B16/SUM(B:B) -> -0.0063649672 | I16: 105
A17: MUDS | B17: 1 | C17: 44301 | D17: 13.33 | E17: 44322 | G17: 0.22655664 | H17: =G17*B17/SUM(B:B) -> 0.0014420256 | I17: 21
A18: COTY | B18: 1 | C18: 44168 | D18: 7.44 | E18: 44327 | G18: 0.21236559 | H18: =G18*B18/SUM(B:B) -> 0.0013517 | I18: 159
A19: CRSP | B19: 1 | C19: 44315 | D19: 136.77 | E19: 44329 | F19: 97.14 | G19: -0.29 | H19: =G19*B19/SUM(B:B) -> -0.0018458405 | I19: 14 | K19: Bryan | L19: 0
A20: BIIB | B20: 1 | C20: 44245 | D20: -55.02 | E20: 44354 | F20: 95.05 | G20: 0.728 | H20: =G20*B20/SUM(B:B) -> 0.0046336961 | I20: 109
A21: SDC | B21: 1 | C21: 44322 | D21: 8.37 | E21: 44362 | G21: 0.18518519 | H21: =G21*B21/SUM(B:B) -> 0.0011786976 | I21: 40
A22: JOAN | B22: 1 | C22: 44294 | D22: 11.99 | E22: 44364 | G22: 0.25145955 | H22: =G22*B22/SUM(B:B) -> 0.0016005318 | I22: 70 | L22: 0.025
A23: CAR | B23: 1 | C23: 44329 | D23: 75.8 | E23: 44365 | F23: 88.065 | G23: 0.162 | H23: =G23*B23/SUM(B:B) -> 0.0010311247 | I23: 36
A24: HOFV | B24: 1 | C24: 44301 | D24: 3.65 | E24: 44376 | G24: 0.1260274 | H24: =G24*B24/SUM(B:B) -> 0.00080216025 | I24: 75
A25: GRWG | B25: 1 | C25: 44327 | D25: 37.45 | E25: 44385 | G25: 0.22176235 | H25: =G25*B25/SUM(B:B) -> 0.0014115101 | I25: 58
A26: MSGE | B26: 1 | C26: 44217 | D26: 91.78 | E26: 44404 | F26: 68.78 | G26: -0.251 | H26: =G26*B26/SUM(B:B) -> -0.0015976068 | I26: 187
A27: APTV | B27: 1 | C27: 44203 | D27: 141.02 | E27: 44420 | F27: 168.45 | G27: 0.195 | H27: =G27*B27/SUM(B:B) -> 0.0012411686 | I27: 217 | K27: Bryan | L27: 0
A28: CARR | B28: 1 | C28: 44273 | D28: 39.22 | E28: 44427 | F28: 51.615 | G28: 0.322 | H28: =G28*B28/SUM(B:B) -> 0.0020495194 | I28: 154
A29: JOAN | B29: 1 | C29: 44383 | D29: 14.5 | E29: 44442 | F29: 10.63 | G29: -0.267 | H29: =G29*B29/SUM(B:B) -> -0.0016994462 | I29: 59 | K29: Karim | L29: 0
A30: SOFI | B30: 1 | C30: 44453 | D30: 14.44 | E30: 44469 | G30: 0.15685596 | H30: =G30*B30/SUM(B:B) -> 0.00099838302 | I30: 16
A31: GRWG | B31: 1 | C31: 44434 | D31: 31.63 | E31: 44473 | F31: 23.72 | G31: -0.25 | H31: =G31*B31/SUM(B:B) -> -0.0015912418 | I31: 39 | K31: Karim | L31: 0
A32: HTZZW | B32: 1 | C32: 44441 | D32: 8.21 | E32: 44477 | G32: 0.3361754 | H32: =G32*B32/SUM(B:B) -> 0.0021397454 | I32: 36
A33: WW | B33: 1 | C33: 44419 | D33: 23.62 | E33: 44480 | F33: 17.71 | G33: -0.25 | H33: =G33*B33/SUM(B:B) -> -0.0015912418 | I33: 61 | K33: Bryan Bottarelli | L33: 0
A34: JSPR | B34: 1 | C34: 44476 | D34: 8.5 | E34: 44482 | G34: 0.50029412 | H34: =G34*B34/SUM(B:B) -> 0.0031843557 | I34: 6
A35: IMAX | B35: 1 | C35: 44455 | D35: 16.82 | E35: 44498 | G35: 0.18252081 | H35: =G35*B35/SUM(B:B) -> 0.001161739 | I35: 43
A36: PLL | B36: 1 | C36: 44406 | D36: 53.94 | E36: 44510 | G36: 0.16777901 | H36: =G36*B36/SUM(B:B) -> 0.0010679079 | I36: 104
A37: ABNB | B37: 2 | C37: 44308 | D37: 153.53 | E37: 44522 | F37: 186.335 | G37: 0.214 | H37: =G37*B37/SUM(B:B) -> 0.002724206 | I37: 214
A38: COTY | B38: 1 | C38: 44364 | D38: 8.8 | E38: 44531 | G38: 0.15681818 | H38: =G38*B38/SUM(B:B) -> 0.00099814259 | I38: 167
A39: JOBY | B39: 1 | C39: 44469 | D39: 9.95 | E39: 44531 | F39: 7.45 | G39: -0.251 | H39: =G39*B39/SUM(B:B) -> -0.0015976068 | I39: 62 | K39: Bryan Bottarelli | L39: 0
A40: CHWY | B40: 1 | C40: 44385 | D40: 80.1 | E40: 44536 | F40: 59.01 | G40: -0.263 | H40: =G40*B40/SUM(B:B) -> -0.0016739864 | I40: 151 | K40: Bryan Bottarelli | L40: 0
...

Sheet closed 2023
A1: Ticker Symbol | B1: Weight | C1: Entry Date | D1: Entry Price | E1: Exit Date | F1: Exit Price | G1: Gain % | I1: Days Held | K1: Open Editor | L1: Dividends | M1: Close Editor
A2: REAL | B2: 1 | C2: 44890 | D2: 1.45 | E2: 44964 | G2: 0.34827586 | H2: =G2*B2/SUM(B:B) -> 0.0071809456 | I2: 74
A3: SOFI | B3: 1 | C3: 44932 | D3: 4.53 | E3: 44966 | G3: 0.38741722 | H3: =G3*B3/SUM(B:B) -> 0.0079879839 | I3: 34
A4: DIS | B4: 1 | C4: 44910 | D4: 92.47 | E4: 44980 | G4: 0.18141019 | H4: =G4*B4/SUM(B:B) -> 0.0037404162 | I4: 70
A5: RTX | B5: 1 | C5: 44854 | D5: 87.81 | E5: 44994 | F5: 96.59 | G5: 0.113 | H5: =G5*B5/SUM(B:B) -> 0.0023298969 | I5: 140 | K5: Bryan Bottarelli | L5: 1.1
A6: DAL | B6: 1 | C6: 44917 | D6: 33.6 | E6: 44995 | F6: 36.96 | G6: 0.1 | H6: =G6*B6/SUM(B:B) -> 0.0020618557 | I6: 78 | K6: Bryan Bottarelli | L6: 0
A7: HBI | B7: 1 | C7: 44812 | D7: 8.69 | E7: 44995 | F7: 5.21 | G7: -0.383 | H7: =G7*B7/SUM(B:B) -> -0.0078969072 | I7: 183 | K7: Karim | L7: 0.15
A8: LVMUY | B8: 1 | C8: 44896 | D8: 151.84 | E8: 44998 | F8: 165.99 | G8: 0.093 | H8: =G8*B8/SUM(B:B) -> 0.0019175258 | I8: 102 | K8: Bryan Bottarelli | L8: 0
A9: SCHW | B9: 1 | C9: 45008 | D9: 56.15 | E9: 45021 | F9: 49 | G9: -0.127 | H9: =G9*B9/SUM(B:B) -> -0.0026185567 | I9: 13 | K9: Karim | L9: 0
A10: ADT | B10: 1 | C10: 44973 | D10: 8.3 | E10: 45048 | F10: 6.2 | G10: -0.249 | H10: =G10*B10/SUM(B:B) -> -0.0051340206 | I10: 75 | K10: Karim | L10: 0.04
A11: SNOW | B11: 1 | C11: 44868 | D11: 146.1 | E11: 45071 | F11: 155.41 | G11: 0.1632 | H11: =G11*B11/SUM(B:B) -> 0.0033649485 | I11: 196 | K11: Bryan Bottarelli
A12: CBOE | B12: 1 | C12: 44994 | D12: 122.91 | E12: 45106 | F12: 92.18 | G12: 0.1053 | H12: =G12*B12/SUM(B:B) -> 0.002171134 | I12: 112 | K12: Bryan Bottarelli
A13: PSTX | B13: 0.5 | C13: 45113 | D13: 1.65 | E13: 45118 | F13: 1.93 | G13: 0.2071 | H13: =G13*B13/SUM(B:B) -> 0.0021350515 | I13: 5 | K13: Karim
A14: AI | B14: 1 | C14: 44966 | D14: 27.46 | E14: 45120 | G14: 0.1857 | H14: =G14*B14/SUM(B:B) -> 0.003828866 | I14: 154 | K14: Bryan Bottarelli
A15: KWEB | B15: 1 | C15: 44903 | D15: 31.21 | E15: 45127 | F15: 28.1 | G15: -0.0996 | H15: =G15*B15/SUM(B:B) -> -0.0020536082 | I15: 224 | K15: Karim
A16: NSPL | B16: 1 | C16: 45057 | D16: 33.09 | E16: 45134 | F16: 35.5 | G16: 0.0728 | H16: =G16*B16/SUM(B:B) -> 0.0015010309 | I16: 77
A17: NSPY | B17: 1 | C17: 45057 | D17: 30 | E17: 45134 | F17: 28.57 | G17: -0.0477 | H17: =G17*B17/SUM(B:B) -> -0.00098350515 | I17: 77
A18: PNC | B18: 1 | C18: 45047 | D18: 124.97 | E18: 45149 | F18: 129.94 | G18: 0.0522 | H18: =G18*B18/SUM(B:B) -> 0.0010762887 | I18: 105 | K18: Karim
A19: USB.PR | B19: 1 | C19: 45026 | D19: 18.84 | E19: 45149 | F19: 16.69 | G19: -0.1008 | H19: =G19*B19/SUM(B:B) -> -0.0020783505 | I19: 126 | K19: Karim | L19: 1.55
A20: AMC | B20: 1 | C20: 45141 | D20: 4.79 | E20: 45152 | F20: 3.33 | G20: -0.3048 | H20: =G20*B20/SUM(B:B) -> -0.0062845361 | I20: 11 | K20: Bryan | L20: 0.25
A21: BOOT | B21: 1 | C21: 44938 | D21: 72.99 | E21: 45155 | F21: 93.41 | G21: 0.2649 | H21: =G21*B21/SUM(B:B) -> 0.0054618557 | I21: =_xlfn.DAYS(E21,C21) -> 217 | K21: Bryan
A22: WBA | B22: 2 | C22: 44791 | D22: 36.26 | E22: 45155 | F22: 27.2 | G22: -0.2233 | H22: =G22*B22/SUM(B:B) -> -0.0092082474 | I22: =_xlfn.DAYS(E22,C22) -> 364 | K22: Karim | L22: 0
A23: NRG | B23: 1 | C23: 44945 | D23: 31.55 | E23: 45162 | F23: 37.35 | G23: 0.2197 | H23: =G23*B23/SUM(B:B) -> 0.0045298969 | I23: =_xlfn.DAYS(E23,C23) -> 217 | K23: Karim
A24: JSPR | B24: 1 | C24: 44959 | D24: 1.77 | E24: 45180 | F24: 0.89 | G24: -0.4972 | H24: =G24*B24/SUM(B:B) -> -0.010251546 | I24: =_xlfn.DAYS(E24,C24) -> 221 | K24: Karim
A25: RTX | B25: 1 | C25: 45022 | D25: 98.77 | E25: 45182 | F25: 74.08 | G25: -0.238 | H25: =G25*B25/SUM(B:B) -> -0.0049072165 | I25: 160 | K25: Bryan Bottarelli
A26: BA | B26: 1 | C26: 44819 | D26: 147.88 | E26: 45187 | F26: 206.64 | G26: 0.3494 | H26: =G26*B26/SUM(B:B) -> 0.0072041237 | I26: 368 | K26: Karim | L26: 0
A27: HTZ | B27: 3 | C27: 44686 | D27: 17.72 | E27: 45195 | F27: 13.29 | G27: -0.25 | H27: =G27*B27/SUM(B:B) -> -0.015463918 | I27: 509 | K27: Bryan Bottarelli
A28: ALB | B28: 1 | C28: 45076 | D28: 200 | E28: 45202 | F28: 160 | G28: -0.196 | H28: =G28*B28/SUM(B:B) -> -0.0040412371 | I28: 126 | K28: Karim
A29: BTG | B29: 1 | C29: 45071 | D29: 3.71 | E29: 45202 | F29: 2.78 | G29: -0.2291 | H29: =G29*B29/SUM(B:B) -> -0.0047237113 | I29: 131 | K29: Karim | L29: 0
A30: GDXJ | B30: 1 | C30: 44952 | D30: 40.92 | E30: 45202 | F30: 30.69 | G30: -0.25 | H30: =G30*B30/SUM(B:B) -> -0.0051546392 | I30: 250 | K30: Bryan Bottarelli | L30: 0
A31: KDP | B31: 1 | C31: 44826 | D31: 37.21 | E31: 45212 | F31: 27.91 | G31: -0.2227 | H31: =G31*B31/SUM(B:B) -> -0.0045917526 | I31: 386 | K31: Bryan Bottarelli | L31: 0
A32: LW | B32: 1 | C32: 45036 | D32: 108.96 | E32: 45212 | F32: 81.72 | G32: -0.2449 | H32: =G32*B32/SUM(B:B) -> -0.0050494845 | I32: 176 | K32: Bryan Bottarelli | L32: 1.02
A33: XBI | B33: 1 | C33: 44798 | D33: 90.5 | E33: 45218 | F33: 67.88 | G33: -0.2499 | H33: =G33*B33/SUM(B:B) -> -0.0051525773 | I33: 420 | K33: Bryan Bottarelli | L33: 1.18
A34: Z | B34: 1 | C34: 45155 | D34: 51.61 | E34: 45222 | F34: 38.54 | G34: -0.2532 | H34: =G34*B34/SUM(B:B) -> -0.0052206186 | I34: 67 | K34: Bryan | L34: 0
A35: ATEC | B35: 1 | C35: 45190 | D35: 12.99 | E35: 45225 | F35: 9.74 | G35: -0.2502 | H35: =G35*B35/SUM(B:B) -> -0.0051587629 | I35: 35 | K35: Karim | L35: 0.8
A36: PFE | B36: 1 | C36: 44987 | D36: 40.06 | E36: 45226 | F36: 30.05 | G36: -0.2294 | H36: =G36*B36/SUM(B:B) -> -0.0047298969 | I36: 239 | K36: Karim | L36: 0.56
A37: GPRO | B37: 1 | C37: 44714 | D37: -2.95 | E37: 45259 | F37: 1.48 | G37: -0.4983 | H37: =G37*B37/SUM(B:B) -> -0.010274227 | I37: 0 | K37: Bryan Bottarelli | L37: 0
A38: PTON240119C00015000 | B38: 1 | C38: 44714 | D38: 5.2 | E38: 45259 | F38: 0.01 | G38: -0.9981 | H38: =G38*B38/SUM(B:B) -> -0.020579381 | I38: 545 | K38: Bryan Bottarelli | L38: 0.82
A39: ALB | B39: 1 | C39: 45204 | D39: 157.21 | E39: 45267 | F39: 121.21 | G39: -0.229 | H39: =G39*B39/SUM(B:B) -> -0.0047216495 | I39: 63 | K39: Karim | L39: 0
A40: RYCEY | B40: 1 | C40: 44651 | D40: 1.14 | E40: 45267 | F40: 3.61 | G40: 2.1667 | H40: =G40*B40/SUM(B:B) -> 0.044674227 | I40: 616 | K40: Karim | L40: 0
...

Sheet YTD
A1: Ticker Symbol | B1: Weight | C1: Entry Date | D1: Entry Price | E1: Exit Date | F1: Exit Price | G1: Gain % | H1: weighted | I1: Days Held | K1: Open Editor | L1: Dividends | M1: Close Editor
A2: ET | B2: 1 | C2: 44827 | D2: 11 | E2: 45309 | F2: 13.57 | G2: 0.3417 | H2: =G2*B2/SUM(B:B) -> 0.018951747 | I2: =_xlfn.DAYS(E2,C2) -> 482 | K2: Karim
A3: TTD | B3: 1 | C3: 45302 | D3: 68.6 | E3: 45366 | F3: 85.64 | G3: 0.2483 | H3: =G3*B3/SUM(B:B) -> 0.013771492 | I3: =_xlfn.DAYS(E3,C3) -> 64 | K3: Bryan
A4: VRTX | B4: 1 | C4: 45239 | D4: 42.27 | E4: 45309 | F4: 51.5 | G4: 0.2184 | H4: =G4*B4/SUM(B:B) -> 0.012113145 | I4: =_xlfn.DAYS(E4,C4) -> 70 | K4: Bryan
A5: ET | B5: 1 | C5: 45026 | D5: 12.5 | E5: 45309 | F5: 13.8 | G5: 0.1784 | H5: =G5*B5/SUM(B:B) -> 0.0098946201 | I5: =_xlfn.DAYS(E5,C5) -> 283 | K5: Karim | L5: 0.93
A6: XLF | B6: 2 | C6: 44343 | D6: 34.81 | E6: 45302 | F6: 37.76 | G6: 0.1372 | H6: =G6*B6/SUM(B:B) -> 0.015219079 | I6: 959 | K6: Bryan | L6: 3.65
A7: SYK | B7: 1 | C7: 45064 | D7: 284 | E7: 45316 | F7: 309.07 | G7: 0.0964 | H7: =G7*B7/SUM(B:B) -> 0.0053466445 | I7: =_xlfn.DAYS(E7,C7) -> 252 | K7: Bryan Bottarelli | L7: 2.3
A8: TJX | B8: 1 | C8: 45197 | D8: 88.58 | E8: 45316 | F8: 95.36 | G8: 0.0803 | H8: =G8*B8/SUM(B:B) -> 0.0044536883 | I8: =_xlfn.DAYS(E8,C8) -> 119 | K8: Bryan | L8: 0.33
A9: VZ | B9: 1 | C9: 45026 | D9: 39.21 | E9: 45309 | F9: 38.53 | G9: 0.0332 | H9: =G9*B9/SUM(B:B) -> 0.0018413755 | I9: =_xlfn.DAYS(E9,C9) -> 283 | K9: Karim | L9: 1.98
A10: XLE | B10: 1 | C10: 45274 | D10: 82.37 | E10: 45323 | F10: 83.91 | G10: 0.0284 | H10: =G10*B10/SUM(B:B) -> 0.0015751525 | I10: =_xlfn.DAYS(E10,C10) -> 49 | K10: Karim | L10: 0.8
A11: SOUN | B11: 1 | C11: 45357 | D11: 5.17 | E11: 45365 | F11: 7.3675 | G11: 0.425 | H11: =G11*B11/SUM(B:B) -> 0.023571825 | I11: =_xlfn.DAYS(E11,C11) -> 8 | K11: Bryan
A12: AJAN | B12: 1 | C12: 45309 | D12: 24.49 | E12: 45379 | F12: 24.86 | G12: 0.0151 | H12: =G12*B12/SUM(B:B) -> 0.00083749307 | I12: =_xlfn.DAYS(E12,C12) -> 70 | K12: Karim | L12: 0
A13: BATRK | B13: 0.03 | C13: 45127 | D13: 39.63 | E13: 45379 | F13: 38.8 | G13: -0.0209 | H13: =G13*B13/SUM(B:B) -> -3.4775374e-05 | I13: =_xlfn.DAYS(E13,C13) -> 252 | L13: 0
A14: FWONA | B14: 2 | C14: 45092 | D14: 65.11 | E14: 45379 | F14: 59.59 | G14: -0.0848 | H14: =G14*B14/SUM(B:B) -> -0.0094065446 | I14: =_xlfn.DAYS(E14,C14) -> 287 | K14: Bryan | L14: 0
A15: MAT | B15: 1 | C15: 45141 | D15: 21.25 | E15: 45379 | F15: 19.78 | G15: -0.0692 | H15: =G15*B15/SUM(B:B) -> -0.0038380477 | I15: =_xlfn.DAYS(E15,C15) -> 238 | K15: Bryan | L15: 0
A16: NEE | B16: 1 | C16: 45162 | D16: 67.89 | E16: 45379 | F16: 63.97 | G16: -0.0364 | H16: =G16*B16/SUM(B:B) -> -0.0020188575 | I16: =_xlfn.DAYS(E16,C16) -> 217 | K16: Karim | L16: 1.45
A17: PEP | B17: 1 | C17: 45078 | D17: 179.98 | E17: 45379 | F17: 174.58 | G17: -0.0089 | H17: =G17*B17/SUM(B:B) -> -0.00049362174 | I17: =_xlfn.DAYS(E17,C17) -> 301 | K17: Bryan Bottarelli | L17: 3.8
A18: PGX | B18: 1 | C18: 44924 | D18: 11.21 | E18: 45379 | F18: 11.99 | G18: 0.1505 | H18: =G18*B18/SUM(B:B) -> 0.0083471991 | I18: =_xlfn.DAYS(E18,C18) -> 455 | K18: Karim | L18: 0.91

Sheet trade consolidation
A1: BOOT | B1: 0.5 | C1: 44938 | D1: 72.99 | E1: 45119 | F1: 91.23 | G1: 62.04 | H1: 0.2499 | I1: =H1*B1/SUM(B:B) -> 0.062475
A2: BOOT | B2: 0.5 | C2: 44938 | D2: 72.99 | E2: 45155 | G2: 93.41 | H2: 0.2798 | I2: =H2*B2/SUM(B:B) -> 0.06995
A3: BOOT | B3: 1 | C3: 44938 | D3: 72.99 | E3: 45155 | H3: =AVERAGE(H1:H2) -> 0.26485
A13: AI consolidated
A14: ET still open - removed
A15: SNOW cons
A16: pstx cons
A17: boot cons
